Workbook

Sheet PCR Summary 
I3: Metro budget | J3: Metro spend | K3: Metro budget auto calculates.
I4: =SUM(D27:D29) -> 0 | J4: =SUM(E27:E29) -> 0
C5: Campaign details | I5: =SUM(D23-I4) -> 0 | J5: =SUM(E23-J4) -> 0
C7: Department or organisation | D7: Dept of XXX | E7: Total media investment (Nett) | F7: =D23 -> 0 | I7: Regional budget* | J7: Regional spend
C8: Campaign name | D8: XXXX | E8: Surplus | F8: =SUM(D23-E23) -> 0 | I8: Add from plan | J8: =SUM('Radio Data'!F23+'OOH Data'!F26+'Direct Digi Data'!D23) -> 0 | K8: Regional spend auto calculates.
C9: Client contact name | D9: XXXX | E9: Buying audience | F9: XXX | I9: Add Activations here: | J9: 0
C10: Client contact email | D10: XXXXX | E10: Campaign timing | F10: XXX | J10: =SUM(J8:J9) -> 0
C11: Client contact phone no. | D11: XXXX | E11: Plan date | F11: XXX | I11: Figure in blue need to be added from Activations PCR
C12: MAMS number | D12: SXX/XX | E12: Plan version | F12: XXX | I12: HIDE THE ABOVE BEFORE SENDING TO THE PLANNING TEAM
C13: Tier | D13: B or C | E13: Campaign/Functional/Recruitment | F13: Campaign / Functional / Recruitment
C15: Media Type | D15: Total Nett Budget | E15: Total Nett Spend | F15: Total Nett Share
C16: Television | D16: ='TV Detail'!F7 -> 0 | E16: ='TV Detail'!F10 -> 0 | F16: =E16/$E$23 -> #DIV/0!
C17: Cinema | D17: ='Cinema Detail'!F7 -> 0 | E17: ='Cinema Detail'!F7 -> 0 | F17: =E17/$E$23 -> #DIV/0!
C18: Press | D18: ='Press Detail'!F7 -> 0 | E18: ='Press Data'!F16 -> 0 | F18: =E18/$E$23 -> #DIV/0!
C19: Radio | D19: ='Radio Detail'!F7 -> 0 | E19: ='Radio Detail'!F8 -> 0 | F19: =E19/$E$23 -> #DIV/0!
C20: Outdoor | D20: ='OOH Detail'!F7 -> 0 | E20: ='OOH Detail'!F8 -> 0 | F20: =E20/$E$23 -> #DIV/0!
C21: Digital - Direct | D21: ='Direct Digi Detail'!H8 -> 0 | E21: ='Direct Digi Detail'!H9 -> 0 | F21: =E21/$E$23 -> #DIV/0!
C22: Digital - Biddable | D22: =D40 -> 0 | F22: =E22/$E$23 -> #DIV/0!
C23: Total | D23: =SUM(D16:D22) -> 0 | E23: =SUM(E16:E22) -> 0 | F23: =SUM(F16:F22) -> #DIV/0!
C25: Market | D25: Total Nett Budget | E25: Nett Spend | F25: Total Nett Share
C26: Metro | D26: =I5 -> 0 | E26: =J5 -> 0 | F26: =E26/$E$23 -> #DIV/0!
C27: Regional | D27: 0 | E27: =J10 -> 0 | F27: =E27/$E$23 -> #DIV/0!
C28: Regional Press | D28: 0 | E28: ='Press Data'!G24 -> 0 | F28: =E28/$E$23 -> #DIV/0!
C29: CALD | D29: =D40 -> 0 | E29: =E40 -> 0 | F29: =E29/$E$23 -> #DIV/0!
C30: Total | D30: =SUM(D26:D29) -> 0 | E30: =SUM(E26:E29) -> 0 | F30: =SUM(F26:F29) -> #DIV/0!
C32: CALD | D32: Total Nett Budget | E32: Nett Spend | F32: Total Nett Share
C33: Television (Not Included in Total CALD Split) | D33: 0 | F33: =E33/$E$23 -> #DIV/0!
C34: Cinema | D34: 0 | F34: =E34/$E$23 -> #DIV/0!
C35: Press | D35: 0 | E35: ='Press Data'!G20 -> 0 | F35: =E35/$E$23 -> #DIV/0!
C36: Radio | D36: 0 | E36: ='Radio Data'!F19 -> 0 | F36: =E36/$E$23 -> #DIV/0!
C37: Outdoor | D37: 0 | E37: ='OOH Data'!F22 -> 0 | F37: =E37/$E$23 -> #DIV/0!
C38: Digital - Direct | D38: 0 | E38: ='Direct Digi Data'!D19 -> 0 | F38: =E38/$E$23 -> #DIV/0!
C39: Digital - Biddable | D39: 0 | F39: =E39/$E$23 -> #DIV/0!
C40: Total | D40: =SUM(D33:D39) -> 0 | E40: =SUM(E33:E39) -> 0 | F40: =SUM(F33:F39) -> #DIV/0!
C41: *Please note this document is not applicable for the purpose of financial / invoice reconciliation. Amounts are nett media only, and exclude MAMS fees, GST, production, translation and adserving*
C43: Media Task:
C53: Campaign Commentary:
D55: Highlights - what worked? | E55: Learnings - what didn’t work? Why? | F55: Recommendation(s) / Solutions
C56: Media & Delivery | D56: XXXX | E56: XXXX | F56: XXXX
C57: Process | D57: XXXX | E57: XXXX | F57: XXXX
...

Sheet TV Detail
C8: On air dates: | D8: DD/MM/YY - DD/MM/YY | E8: CAD rating | F8: X
C9: TVC durations: | D9: xx | E9: Budget (Nett): | F9: 0
C10: Buying audience: | D10: xx | E10: Spend (Nett): | F10: ='TV Data'!D30 -> 0
C11: Peak / off peak: | D11: xx | E11: Savings (Nett): | F11: =SUM(F9-F10) -> 0
C12: Frequency goal: | D12: xx | E12: Bonus Value @ Client (Nett): | F12: =SUM('TV Data'!F19:G26) -> 0
C14: TV Commentary
D16: Highlights - what worked? | E16: Learnings - what didn’t work? Why? | F16: Recommendation(s) / Solutions
C17: Media & Delivery | D17: XXX | E17: XXX | F17: XXX
C18: Process | D18: XXX | E18: XXX | F18: XXX
C20: Campaign Delivery
C44: Metro 5 City Panel Plus Subscription, w35-54, MxM
C67: Regional Panel Plus Subscription, w35-54, MxM

Sheet TV Data
B2: *Refer to Overview Data tab in BRAT to complete data tables
B3: Note: Please ensure you are using tarps minus stv in the below
D5: TARPs | F5: REACH
B6: SMD Market | C6: Chart name | D6: Bought | E6: Delivered | F6: Planned | G6: Delivered
B7: Sydney | C7: Syd | D7: 0 | E7: 0 | F7: 0 | G7: 0
B8: Melbourne | C8: Melb | D8: 0 | E8: 0 | F8: 0 | G8: 0
B9: Brisbane | C9: Bris | D9: 0 | E9: 0 | F9: 0 | G9: 0
B10: Adelaide | C10: Adel | D10: 0 | E10: 0 | F10: 0 | G10: 0
B11: Perth | C11: Perth | D11: 0 | E11: 0 | F11: 0 | G11: 0
B12: Northern NSW Aggregated | C12: Nth NSW | D12: 0 | E12: 0 | F12: 0 | G12: 0
B13: Southern NSW Aggregated | C13: Sth NSW | D13: 0 | E13: 0 | F13: 0 | G13: 0
B14: Victoria Aggregated | C14: VIC | D14: 0 | E14: 0 | F14: 0 | G14: 0
B15: Queensland Aggregated | C15: QLD | D15: 0 | E15: 0 | F15: 0 | G15: 0
B16: Tasmania Aggregated | C16: Tas | D16: 0 | E16: 0 | F16: 0 | G16: 0
B18: Network | C18: Chart name | D18: Spends (Gross) | F18: Bonus (Gross)
B19: Network Seven | C19: Seven | D19: 0 | F19: 0
B20: Network Nine | C20: Nine | D20: 0 | F20: 0
B21: Network Ten | C21: Ten | D21: 0 | F21: 0
B22: SBS Metro | C22: SBS | D22: 0 | F22: 0
B23: Seven Affiliate Sales | C23: SAS | D23: 0 | F23: 0
B24: Southern Cross Austereo | C24: SCA | D24: 0 | F24: 0
B25: WIN | C25: WIN | D25: 0 | F25: 0
B26: SBS Regional | C26: SBS | D26: 0 | F26: 0
C29: GROSS | D29: =SUM(D19:E26) -> 0 | F29: =SUM(F19:G26) -> 0
C30: NETT | D30: =SUM(D29*0.9) -> 0 | F30: =SUM(F29*0.9) -> 0

Sheet Cinema Detail
C6: In-market dates: | D6: xx/xx/xxxx - xx/xx/xxxx | E6: Budget (Nett): | F6: 0
C7: Placement | D7: xx | E7: Spend (Nett): | F7: ='Cinema Data'!F15 -> 0
C8: Ad Sizes | D8: xx | E8: Savings (Nett): | F8: =SUM(F6-F7) -> 0
E9: Bonus Value @ Client (Nett): | F9: ='Cinema Data'!G9 -> 0
C11: Cinema Commentary:
D13: Highlights - what worked? | E13: Learnings - what didn’t work? Why? | F13: Recommendation(s) / Solutions
C14: Media & Delivery | D14: XXX | E14: XXX | F14: XXX
C15: Process | D15: XXX | E15: XXX | F15: XXX
C41: UPDATE WITH RELEVANT MOVIES - From the PCR sent through by Media Provider
C43: Campaign Delivery
C46: Media Type | D46: ='Cinema Data'!D2 -> Est Audience | E46: ='Cinema Data'!E2 -> Delivered Audience | F46: Bonus @ Client Rates (Nett)
C47: ='Cinema Data'!C3 -> VMO | D47: ='Cinema Data'!D3 -> 0 | E47: ='Cinema Data'!E3 -> 0 | F47: ='Cinema Data'!G9 -> 0
C48: Total | D48: =SUM(D47:D47) -> 0 | E48: =SUM(E47:E47) -> 0 | F48: =SUM(F47:F47) -> 0

Sheet Cinema Data
B2: Metro Provider | D2: Est Audience | E2: Delivered Audience | F2: Spends (Gross) | G2: Bonus (Gross)
B3: Val Morgan | C3: VMO | D3: 0 | E3: 0 | F3: 0 | G3: 0
B5: Regional Provider | D5: Est Audience | E5: Delivered Audience | F5: Spends (Gross) | G5: Bonus (Gross)
B6: Val Morgan | C6: VMO | D6: 0 | E6: 0 | F6: 0 | G6: 0
E8: GROSS | F8: =SUM(F3) -> 0 | G8: =SUM(G3) -> 0
E9: NETT | F9: =SUM(F3*0.9) -> 0 | G9: =SUM(G3*0.9) -> 0
E11: REGIONAL
E12: GROSS | F12: =SUM(F6) -> 0 | G12: =SUM(G6) -> 0
E13: NETT | F13: =F12*0.9 -> 0 | G13: =G12*0.9 -> 0

Sheet Press Detail
C7: In-market dates: | D7: DD/MM/YY - DD/MM/YY | E7: Budget (Nett): | F7: 0
C8: Placement | D8: xx | E8: Spend (Nett): | F8: ='Press Data'!F16 -> 0
C9: Ad Sizes | D9: xx | E9: Savings (Nett): | F9: =SUM(F7-F8) -> 0
E10: Bonus Value @ Client (Nett): | F10: =F32 -> 0
C12: Campaign Commentary:
D14: Highlights - what worked? | E14: Learnings - what didn’t work? Why? | F14: Recommendation(s) / Solutions
C15: Media & Delivery | D15: XXX | E15: XXX | F15: XXX
C16: Process | D16: XXX | E16: XXX | F16: XXX
C18: Campaign Delivery
C21: Media Type | D21: Inserts Booked | E21: Inserts Delivered | F21: Bonus @ Client Rates (Nett)
C22: ='Press Data'!C3 -> Newscorp | D22: ='Press Data'!D3 -> 0 | E22: ='Press Data'!E3 -> 0 | F22: {='Press Data'!H3:H3} -> 0
C23: ='Press Data'!C4 -> Nine | D23: ='Press Data'!D4 -> 0 | E23: ='Press Data'!E4 -> 0 | F23: {='Press Data'!H4:H4} -> 0
C24: ='Press Data'!C5 -> xxx | D24: ='Press Data'!D5 -> 0 | E24: ='Press Data'!E5 -> 0 | F24: {='Press Data'!H5:H5} -> 0
C25: ='Press Data'!C6 -> RMC | D25: ='Press Data'!D6 -> 0 | E25: ='Press Data'!E6 -> 0 | F25: {='Press Data'!H6:H6} -> 0
C26: ='Press Data'!C7 -> ACM | D26: ='Press Data'!D7 -> 0 | E26: ='Press Data'!E7 -> 0 | F26: {='Press Data'!H7:H7} -> 0
C27: ='Press Data'!C8 -> CNAV | D27: ='Press Data'!D8 -> 0 | E27: ='Press Data'!E8 -> 0 | F27: {='Press Data'!H8:H8} -> 0
C28: ='Press Data'!C9 -> Newscorp | D28: ='Press Data'!D9 -> 0 | E28: ='Press Data'!E9 -> 0 | F28: {='Press Data'!H9:H9} -> 0
C29: ='Press Data'!C10 -> BOFB | D29: ='Press Data'!D10 -> 0 | E29: ='Press Data'!E10 -> 0 | F29: {='Press Data'!H10:H10} -> 0
C30: ='Press Data'!C11 -> LEBA | D30: ='Press Data'!D11 -> 0 | E30: ='Press Data'!E11 -> 0 | F30: {='Press Data'!H11:H11} -> 0
C31: ='Press Data'!C12 -> xxx | D31: ='Press Data'!D12 -> 0 | E31: ='Press Data'!E12 -> 0 | F31: {='Press Data'!H12:H12} -> 0
C32: Total | D32: =SUM(D22:D31) -> 0 | E32: =SUM(E22:E31) -> 0 | F32: =SUM(F22:F31) -> 0

Sheet Press Data
B2: Publisher | D2: Inserts Booked | E2: Inserts Delivered | F2: Spends (Gross) | G2: Bonus (Gross) | H2: Bonus (Nett)
A3: Metro Publisher | B3: Newscorp | C3: =B3 -> Newscorp | D3: 0 | E3: 0 | F3: 0 | G3: 0 | H3: =SUM(G3*0.9) -> 0
B4: Nine | C4: =B4 -> Nine | D4: 0 | E4: 0 | F4: 0 | G4: 0 | H4: =SUM(G4*0.9) -> 0
B5: xxx | C5: =B5 -> xxx | D5: 0 | E5: 0 | F5: 0 | G5: 0 | H5: =SUM(G5*0.9) -> 0
A6: Regional Publisher | B6: RMC | C6: =B6 -> RMC | D6: 0 | E6: 0 | F6: 0 | G6: 0 | H6: =SUM(G6*0.9) -> 0
B7: ACM | C7: =B7 -> ACM | D7: 0 | E7: 0 | F7: 0 | G7: 0 | H7: =SUM(G7*0.9) -> 0
B8: CNAV | C8: =B8 -> CNAV | D8: 0 | E8: 0 | F8: 0 | G8: 0 | H8: =SUM(G8*0.9) -> 0
B9: Newscorp | C9: =B9 -> Newscorp | D9: 0 | E9: 0 | F9: 0 | G9: 0 | H9: =SUM(G9*0.9) -> 0
B10: BOFB | C10: =B10 -> BOFB | D10: 0 | E10: 0 | F10: 0 | G10: 0 | H10: =SUM(G10*0.9) -> 0
A11: CALD Network | B11: LEBA | C11: =B11 -> LEBA | D11: 0 | E11: 0 | F11: 0 | G11: 0 | H11: =SUM(G11*0.9) -> 0
B12: xxx | C12: xxx | D12: 0 | E12: 0 | F12: 0 | G12: 0 | H12: 0
B13: xxx | C13: =B13 -> xxx | D13: 0 | E13: 0 | F13: 0 | G13: 0 | H13: =SUM(G13*0.9) -> 0
E15: GROSS | F15: =SUM(F3:F13) -> 0 | G15: =SUM(G3:G13) -> 0
E16: NETT | F16: =SUM(F15*0.9) -> 0 | G16: =SUM(G15*0.9) -> 0
F18: CALD
F19: GROSS | G19: =SUM(F11:F13) -> 0
F20: NETT | G20: =G19*0.9 -> 0
F22: REGIONAL
F23: GROSS | G23: =SUM(F6:F10) -> 0
F24: NETT | G24: =G23*0.9 -> 0

Sheet Radio Detail
C7: In-market dates: | D7: DD/MM/YY - DD/MM/YY | E7: Budget (Nett): | F7: 0
C8: Durations: | D8: xx | E8: Spend (Nett): | F8: ='Radio Data'!F15 -> 0
C9: Buying audience: | D9: xx | E9: Savings (Nett): | F9: =SUM(F7-F8) -> 0
C10: Dayparts | D10: xx | E10: Bonus Value @ Client (Nett): | F10: =SUM(F32) -> 0
C12: Campaign Commentary:
D14: Highlights - what worked? | E14: Learnings - what didn’t work? Why? | F14: Recommendation(s) / Solutions
C15: Media & Delivery | D15: XXX | E15: XXX | F15: XXX
C16: Process | D16: XXX | E16: XXX | F16: XXX
C18: Campaign Delivery
C21: Media Type | D21: Spots Booked | E21: Spots Delivered | F21: Bonus @ Client Rates (Nett)
C22: ='Radio Data'!C3 -> SCA | D22: ='Radio Data'!D3 -> 0 | E22: ='Radio Data'!E3 -> 0 | F22: {='Radio Data'!H3:H3} -> 0
C23: ='Radio Data'!C4 -> NOVA | D23: ='Radio Data'!D4 -> 0 | E23: ='Radio Data'!E4 -> 0 | F23: {='Radio Data'!H4:H4} -> 0
C24: ='Radio Data'!C5 -> ARN | D24: ='Radio Data'!D5 -> 0 | E24: ='Radio Data'!E5 -> 0 | F24: {='Radio Data'!H5:H5} -> 0
C25: ='Radio Data'!C6 -> Nine | D25: ='Radio Data'!D6 -> 0 | E25: ='Radio Data'!E6 -> 0 | F25: {='Radio Data'!H6:H6} -> 0
C26: ='Radio Data'!C7 -> ATN | D26: ='Radio Data'!D7 -> 0 | E26: ='Radio Data'!E7 -> 0 | F26: {='Radio Data'!H7:H7} -> 0
C27: ='Radio Data'!C8 -> SCA | D27: ='Radio Data'!D8 -> 0 | E27: ='Radio Data'!E8 -> 0 | F27: {='Radio Data'!H8:H8} -> 0
C28: ='Radio Data'!C9 -> TRSN | D28: ='Radio Data'!D9 -> 0 | E28: ='Radio Data'!E9 -> 0 | F28: {='Radio Data'!H9:H9} -> 0
C29: ='Radio Data'!C10 -> ATN | D29: ='Radio Data'!D10 -> 0 | E29: ='Radio Data'!E10 -> 0 | F29: {='Radio Data'!H10:H10} -> 0
C30: ='Radio Data'!C11 -> LEBA | D30: ='Radio Data'!D11 -> 0 | E30: ='Radio Data'!E11 -> 0 | F30: {='Radio Data'!H11:H11} -> 0
C31: ='Radio Data'!C12 -> SBS | D31: ='Radio Data'!D12 -> 0 | E31: ='Radio Data'!E12 -> 0 | F31: {='Radio Data'!H12:H12} -> 0
C32: Total | D32: =SUM(D22:D31) -> 0 | E32: =SUM(E22) -> 0 | F32: ='Radio Data'!G15 -> 0

Sheet Radio Data
B2: Network | C2: Chart Station Name | D2: Spots Booked | E2: Spots Delivered | F2: Spends (Gross) | G2: Bonus (Gross) | H2: Bonus (Nett)
A3: Metro Network | B3: SCA | C3: =B3 -> SCA | D3: 0 | E3: 0 | F3: 0 | G3: 0 | H3: =SUM(G3*0.9) -> 0
B4: NOVA | C4: =B4 -> NOVA | D4: 0 | E4: 0 | F4: 0 | G4: 0 | H4: =SUM(G4*0.9) -> 0
B5: ARN | C5: =B5 -> ARN | D5: 0 | E5: 0 | F5: 0 | G5: 0 | H5: =SUM(G5*0.9) -> 0
B6: Nine | C6: =B6 -> Nine | D6: 0 | E6: 0 | F6: 0 | G6: 0 | H6: =SUM(G6*0.9) -> 0
B7: ATN | C7: =B7 -> ATN | D7: 0 | E7: 0 | F7: 0 | G7: 0 | H7: =SUM(G7*0.9) -> 0
A8: Regional Network | B8: SCA | C8: =B8 -> SCA | D8: 0 | E8: 0 | F8: 0 | G8: 0 | H8: =SUM(G8*0.9) -> 0
B9: TRSN | C9: =B9 -> TRSN | D9: 0 | E9: 0 | F9: 0 | G9: 0 | H9: =SUM(G9*0.9) -> 0
B10: ATN | C10: =B10 -> ATN | D10: 0 | E10: 0 | F10: 0 | G10: 0 | H10: =SUM(G10*0.9) -> 0
A11: CALD Network | B11: LEBA | C11: =B11 -> LEBA | D11: 0 | E11: 0 | F11: 0 | G11: 0 | H11: =SUM(G11*0.9) -> 0
B12: SBS | C12: =B12 -> SBS | D12: 0 | E12: 0 | F12: 0 | G12: 0 | H12: =SUM(G12*0.9) -> 0
E14: GROSS | F14: =SUM(F3:F12) -> 0 | G14: =SUM(G3:G12) -> 0
E15: NETT | F15: =SUM(F14*0.9) -> 0 | G15: =SUM(G14*0.9) -> 0
E17: CALD
E18: GROSS | F18: =SUM(F11:F12) -> 0
E19: NETT | F19: =SUM(F18*0.9) -> 0
E21: REGIONAL
E22: GROSS | F22: =SUM(F8:F10) -> 0
E23: NETT | F23: =SUM(F22*0.9) -> 0

Sheet OOH Detail
C7: In-market dates: | D7: DD/MM/YY - DD/MM/YY | E7: Budget (Nett): | F7: 0
C8: Placement | D8: xx | E8: Spend (Nett): | F8: ='OOH Data'!F18 -> 0
C9: Ad Sizes | D9: xx | E9: Savings (Nett): | F9: =SUM(F7-F8) -> 0
E10: Bonus Value @ Client (Nett): | F10: ='OOH Data'!G18 -> 0
C12: Campaign Commentary:
D14: Highlights - what worked? | E14: Learnings - what didn’t work? Why? | F14: Recommendation(s) / Solutions
C15: Media & Delivery | D15: XXX | E15: XXX | F15: XXX
C16: Process | D16: XXX | E16: XXX | F16: XXX
C18: Campaign Delivery
C20: Media Type | D20: Panels Booked | E20: Panels Delivered | F20: Bonus @ Client Rates (Nett)
C21: ='OOH Data'!C3 -> JCDecaux | D21: ='OOH Data'!D3 -> 0 | E21: ='OOH Data'!E3 -> 0 | F21: {='OOH Data'!G3:G3*0.9} -> 0
C22: ='OOH Data'!C4 -> oOh! Media | D22: ='OOH Data'!D4 -> 0 | E22: ='OOH Data'!E4 -> 0 | F22: {='OOH Data'!G4:G4*0.9} -> 0
C23: ='OOH Data'!C5 -> QMS | D23: ='OOH Data'!D5 -> 0 | E23: ='OOH Data'!E5 -> 0 | F23: {='OOH Data'!G5:G5*0.9} -> 0
C24: ='OOH Data'!C6 -> Cartology (Shopper) | D24: ='OOH Data'!D6 -> 0 | E24: ='OOH Data'!E6 -> 0 | F24: {='OOH Data'!G6:G6*0.9} -> 0
C25: ='OOH Data'!C7 -> Val Morgan Outdoor | D25: ='OOH Data'!D7 -> 0 | E25: ='OOH Data'!E7 -> 0 | F25: {='OOH Data'!G7:G7*0.9} -> 0
C26: ='OOH Data'!C8 -> The Media Shop | D26: ='OOH Data'!D8 -> 0 | E26: ='OOH Data'!E8 -> 0 | F26: {='OOH Data'!G8:G8*0.9} -> 0
C27: ='OOH Data'!C9 -> Cartology (Shopper) | D27: ='OOH Data'!D9 -> 0 | E27: ='OOH Data'!E9 -> 0 | F27: {='OOH Data'!G9:G9*0.9} -> 0
C28: ='OOH Data'!C10 -> Val Morgan Outdoor | D28: ='OOH Data'!D10 -> 0 | E28: ='OOH Data'!E10 -> 0 | F28: {='OOH Data'!G10:G10*0.9} -> 0
C29: ='OOH Data'!C11 -> The Media Shop | D29: ='OOH Data'!D11 -> 0 | E29: ='OOH Data'!E11 -> 0 | F29: {='OOH Data'!G11:G11*0.9} -> 0
C30: ='OOH Data'!C12 -> Gawk Outdoor | D30: ='OOH Data'!D12 -> 0 | E30: ='OOH Data'!E12 -> 0 | F30: {='OOH Data'!G12:G12*0.9} -> 0
C31: ='OOH Data'!C13 -> The Media Shop | D31: ='OOH Data'!D13 -> 0 | E31: ='OOH Data'!E13 -> 0 | F31: {='OOH Data'!G13:G13*0.9} -> 0
C32: Total | D32: =SUM(D21:D31) -> 0 | E32: =SUM(E21:E31) -> 0 | F32: ='OOH Data'!G18 -> 0

Sheet OOH Data
B2: Provider | D2: Panels Booked | E2: Panels Delivered | F2: Spends (Gross) | G2: Bonus (Gross)
A3: Metro Provider | B3: JCDecaux | C3: =B3 -> JCDecaux | D3: 0 | E3: 0 | F3: 0 | G3: 0
B4: oOh! Media | C4: =B4 -> oOh! Media | D4: 0 | E4: 0 | F4: 0 | G4: 0
B5: QMS | C5: =B5 -> QMS | D5: 0 | E5: 0 | F5: 0 | G5: 0
B6: Cartology (Shopper) | C6: =B6 -> Cartology (Shopper) | D6: 0 | E6: 0 | F6: 0 | G6: 0
B7: Val Morgan Outdoor | C7: =B7 -> Val Morgan Outdoor | D7: 0 | E7: 0 | F7: 0 | G7: 0
B8: The Media Shop | C8: =B8 -> The Media Shop | D8: 0 | E8: 0 | F8: 0 | G8: 0
A9: Regional Provider | B9: Cartology (Shopper) | C9: =B9 -> Cartology (Shopper) | D9: 0 | E9: 0 | F9: 0 | G9: 0
B10: Val Morgan Outdoor | C10: =B10 -> Val Morgan Outdoor | D10: 0 | E10: 0 | F10: 0 | G10: 0
B11: The Media Shop | C11: =B11 -> The Media Shop | D11: 0 | E11: 0 | F11: 0 | G11: 0
B12: Gawk Outdoor | C12: =B12 -> Gawk Outdoor | D12: 0 | E12: 0 | F12: 0 | G12: 0
A13: CALD Provider | B13: The Media Shop | C13: =B13 -> The Media Shop | D13: 0 | E13: 0 | F13: 0 | G13: 0
B14: S&J | C14: =B14 -> S&J | D14: 0 | E14: 0 | F14: 0 | G14: 0
B15: Locus Outdoor | C15: =B15 -> Locus Outdoor | D15: 0 | E15: 0 | F15: 0 | G15: 0
E17: GROSS | F17: =SUM(F3:F15) -> 0 | G17: =SUM(G3:G15) -> 0
E18: NETT | F18: =SUM(F17*0.9) -> 0 | G18: =SUM(G17*0.9) -> 0
E20: CALD
E21: GROSS | F21: =SUM(F13:F15) -> 0
E22: NETT | F22: =SUM(F21*0.9) -> 0
E24: REGIONAL
E25: GROSS | F25: =SUM(F9:F12) -> 0
E26: NETT | F26: =SUM(F25*0.9) -> 0

Sheet Direct Digi Detail
C8: In-market dates: | D8: DD/MM/YY - DD/MM/YY | F8: Budget (Nett): | H8: 0
C9: Placement | D9: Various - Refer to Media Plan | F9: Spend (Nett): | H9: ='Direct Digi Data'!D15 -> 0
C10: Ad Sizes | D10: Standard Display | F10: Savings (Nett): | H10: =SUM(H8-H9) -> 0
F11: Bonus Value @ Client (Nett): | H11: =I31 -> 0
C12: Campaign Commentary:
D14: Highlights - what worked? | F14: Learnings - what didn’t work? Why? | H14: Recommendation(s) / Solutions
C15: Media & Delivery | D15: XXX | F15: XXX | H15: XXX
C16: Process | D16: XXX | F16: XXX | H16: XXX
C18: Campaign Delivery
C20: Media Type | D20: Impressions Booked | E20: Impressions Delivered | F20: Clicks/Views Delivered | G20: CPM | H20: CTR / VTR | I20: Bonus @ Client Rates (Nett)
C21: ='Direct Digi Data'!C3 -> SEEK | D21: ='Direct Digi Data'!G3 -> 0 | E21: ='Direct Digi Data'!H3 -> 0 | F21: ='Direct Digi Data'!I3 -> 0 | G21: ='Direct Digi Data'!J3 -> #DIV/0! | H21: ='Direct Digi Data'!K3 -> #DIV/0! | I21: ='Direct Digi Data'!E3*0.9 -> 0
C22: ='Direct Digi Data'!C4 -> SBS | D22: ='Direct Digi Data'!G4 -> 0 | E22: ='Direct Digi Data'!H4 -> 0 | F22: ='Direct Digi Data'!I4 -> 0 | G22: ='Direct Digi Data'!J4 -> #DIV/0! | H22: ='Direct Digi Data'!K4 -> #DIV/0! | I22: ='Direct Digi Data'!E4*0.9 -> 0
C23: ='Direct Digi Data'!C5 -> NINE | D23: ='Direct Digi Data'!G5 -> 0 | E23: ='Direct Digi Data'!H5 -> 0 | F23: ='Direct Digi Data'!I5 -> 0 | G23: ='Direct Digi Data'!J5 -> #DIV/0! | H23: ='Direct Digi Data'!K5 -> #DIV/0! | I23: ='Direct Digi Data'!E5*0.9 -> 0
C24: ='Direct Digi Data'!C6 -> TEN | D24: ='Direct Digi Data'!G6 -> 0 | E24: ='Direct Digi Data'!H6 -> 0 | F24: ='Direct Digi Data'!I6 -> 0 | G24: ='Direct Digi Data'!J6 -> #DIV/0! | H24: ='Direct Digi Data'!K6 -> #DIV/0! | I24: ='Direct Digi Data'!E6*0.9 -> 0
C25: ='Direct Digi Data'!C7 -> xxx | D25: ='Direct Digi Data'!G7 -> 0 | E25: ='Direct Digi Data'!H7 -> 0 | F25: ='Direct Digi Data'!I7 -> 0 | G25: ='Direct Digi Data'!J7 -> #DIV/0! | H25: ='Direct Digi Data'!K7 -> #DIV/0! | I25: ='Direct Digi Data'!E7*0.9 -> 0
C26: ='Direct Digi Data'!C8 -> xxx | D26: ='Direct Digi Data'!G8 -> 0 | E26: ='Direct Digi Data'!H8 -> 0 | F26: ='Direct Digi Data'!I8 -> 0 | G26: ='Direct Digi Data'!J8 -> #DIV/0! | H26: ='Direct Digi Data'!K8 -> #DIV/0! | I26: ='Direct Digi Data'!E8*0.9 -> 0
C27: ='Direct Digi Data'!C9 -> xxx | D27: ='Direct Digi Data'!G9 -> 0 | E27: ='Direct Digi Data'!H9 -> 0 | F27: ='Direct Digi Data'!I9 -> 0 | G27: ='Direct Digi Data'!J9 -> #DIV/0! | H27: ='Direct Digi Data'!K9 -> #DIV/0! | I27: ='Direct Digi Data'!E9*0.9 -> 0
C28: ='Direct Digi Data'!C10 -> xxx | D28: ='Direct Digi Data'!G10 -> 0 | E28: ='Direct Digi Data'!H10 -> 0 | F28: ='Direct Digi Data'!I10 -> 0 | G28: ='Direct Digi Data'!J10 -> #DIV/0! | H28: ='Direct Digi Data'!K10 -> #DIV/0! | I28: ='Direct Digi Data'!E10*0.9 -> 0
C29: ='Direct Digi Data'!C11 -> S&J (Weibo) | D29: ='Direct Digi Data'!G11 -> 0 | E29: ='Direct Digi Data'!H11 -> 0 | F29: ='Direct Digi Data'!I11 -> 0 | G29: ='Direct Digi Data'!J11 -> #DIV/0! | H29: ='Direct Digi Data'!K11 -> #DIV/0! | I29: ='Direct Digi Data'!E11*0.9 -> 0
C30: ='Direct Digi Data'!C12 -> InMobi | D30: ='Direct Digi Data'!G12 -> 0 | E30: ='Direct Digi Data'!H12 -> 0 | F30: ='Direct Digi Data'!I12 -> 0 | G30: ='Direct Digi Data'!J12 -> #DIV/0! | H30: ='Direct Digi Data'!K12 -> #DIV/0! | I30: ='Direct Digi Data'!E12*0.9 -> 0
C31: Total | D31: ='Direct Digi Data'!G13 -> 0 | E31: ='Direct Digi Data'!H13 -> 0 | F31: ='Direct Digi Data'!I13 -> 0 | G31: ='Direct Digi Data'!J13 -> #DIV/0! | H31: ='Direct Digi Data'!K13 -> #DIV/0! | I31: ='Direct Digi Data'!E15 -> 0

Sheet Direct Digi Data
B2: Provider | D2: Spends (Gross) | E2: Bonus (Gross) | G2: Booked Impressions | H2: Delivered Impressions | I2: Delivered Clicks / Views | J2: CPM | K2: CTR/VTR
A3: Metro Provider | B3: SEEK | C3: =B3 -> SEEK | D3: 0 | E3: 0 | G3: 0 | H3: 0 | I3: 0 | J3: =SUM(D3/H3*1000) -> #DIV/0! | K3: =SUM(I3/H3) -> #DIV/0!
B4: SBS | C4: =B4 -> SBS | D4: 0 | E4: 0 | G4: 0 | H4: 0 | I4: 0 | J4: =SUM(D4/H4*1000) -> #DIV/0! | K4: =SUM(I4/H4) -> #DIV/0!
B5: NINE | C5: =B5 -> NINE | D5: 0 | E5: 0 | G5: 0 | H5: 0 | I5: 0 | J5: =SUM(D5/H5*1000) -> #DIV/0! | K5: =SUM(I5/H5) -> #DIV/0!
B6: TEN | C6: =B6 -> TEN | D6: 0 | E6: 0 | G6: 0 | H6: 0 | I6: 0 | J6: =SUM(D6/H6*1000) -> #DIV/0! | K6: =SUM(I6/H6) -> #DIV/0!
B7: xxx | C7: =B7 -> xxx | D7: 0 | E7: 0 | G7: 0 | H7: 0 | I7: 0 | J7: =SUM(D7/H7*1000) -> #DIV/0! | K7: =SUM(I7/H7) -> #DIV/0!
A8: Regional Provider | B8: xxx | C8: =B8 -> xxx | D8: 0 | E8: 0 | G8: 0 | H8: 0 | I8: 0 | J8: =SUM(D8/H8*1000) -> #DIV/0! | K8: =SUM(I8/H8) -> #DIV/0!
B9: xxx | C9: =B9 -> xxx | D9: 0 | E9: 0 | G9: 0 | H9: 0 | I9: 0 | J9: =SUM(D9/H9*1000) -> #DIV/0! | K9: =SUM(I9/H9) -> #DIV/0!
B10: xxx | C10: =B10 -> xxx | D10: 0 | E10: 0 | G10: 0 | H10: 0 | I10: 0 | J10: =SUM(D10/H10*1000) -> #DIV/0! | K10: =SUM(I10/H10) -> #DIV/0!
A11: CALD Provider | B11: S&J (Weibo) | C11: S&J (Weibo) | D11: 0 | E11: 0 | G11: 0 | H11: 0 | I11: 0 | J11: =SUM(D11/H11*1000) -> #DIV/0! | K11: =SUM(I11/H11) -> #DIV/0!
B12: InMobi | C12: =B12 -> InMobi | D12: 0 | E12: 0 | G12: 0 | H12: 0 | I12: 0 | J12: =SUM(D12/H12*1000) -> #DIV/0! | K12: =SUM(I12/H12) -> #DIV/0!
G13: =SUM(G3:G12) -> 0 | H13: =SUM(H3:H12) -> 0 | I13: =SUM(I3:I12) -> 0 | J13: =AVERAGE(J3:J12) -> #DIV/0! | K13: =AVERAGE(K3:K12) -> #DIV/0! | L13: Average CPM / CTR
C14: GROSS | D14: =SUM(D3:D12) -> 0 | E14: =SUM(E3:E12) -> 0
C15: NETT | D15: =D14*0.9 -> 0 | E15: =E14*0.9 -> 0
C17: CALD
C18: GROSS | D18: =SUM(D11:D12) -> 0 | E18: =SUM(E7:E16) -> 0
C19: NETT | D19: =D18*0.9 -> 0 | E19: =E18*0.9 -> 0
C21: REGIONAL
C22: GROSS | D22: =SUM(D8:D10) -> 0 | E22: =SUM(E11:E20) -> 0
C23: NETT | D23: =D22*0.9 -> 0 | E23: =E22*0.9 -> 0
